Workbook
Name INTERNET: #REF!
Name LLAMADAS: #REF!
Name SegmentaciónDeDatos_OBJECIÓN: #REF!
Name SERVICIO: #REF!
Name WIN: #REF!

Sheet SPEECH
E2: PASO 1
A3: CICLO DE FACTURACIÓN | B3: PLAN TARIFARIO | D3: Power 59.90 | F3: ENTREGA | H3: CHIP
D4: PASO 2
B5: ELIGE EL MES | C5: FEBRERO | E5: TOTAL DÍAS | F5: =IFERROR(VLOOKUP(C5,FACTURACION!B3:C14,2,0),"") -> 28 | O5: PROMO DSCTO PORTABILIDAD
O6: APLICA PARA LA PRIMERA PORTA
B7: FECHA DE ACTIVACIÓN | C7: 29 | D7: ¿Cliente cuenta con líneas activas postpago en entel? | F7: NO | O7: COSTO MENSUAL | P7: DSCTO | Q7: DSCTO + PROPORCIONAL
D9: CUÁL ES SU CICLO DE FACT? | F9: 5 | L9: PLANES | M9: 50% X 12 MESES (CLARO/MOV/BITEL) | O9: 59.9 | P9: =O9*0.5 -> 29.95 | Q9: =P9+J11 -> 29.95 | R9: 20% x 3 MESES (MOVISTAR)
C10: PASO 3 | H10: SOLO X EL 1ER MES | O10: 69.9 | P10: =O10*0.5 -> 34.95 | Q10: =P10+J11 -> 34.95 | R10: 50% x 12 MESES (MOV - CLARO - BITEL)
B11: =IF(F7="No","CICLO DE FACTURACIÓN A ASIGNAR","CICLO DE FACTURACIÓN ANTERIOR") -> CICLO DE FACTURACIÓN A ASIGNAR | D11: =IF(F7="SI",F9,VLOOKUP(C7,FACTURACION!F3:G33,2,0)) -> 1 | E11: =IFERROR((D13-U16)&" DÍA(S) DE PRORRATEO","") -> 0 DÍA(S) DE PRORRATEO | H11: RENTA PROPORCIONAL (APROXIMADAMENTE) | J11: =(VLOOKUP($D$3,'PLANES REGULARES'!$C$4:$D$11,2,0)/(F13-(D13-1)))*(D13-U16) -> 0 | O11: 79.9 | P11: =O11*0.5 -> 39.95 | Q11: =P11+J11 -> 39.95
E12: VENCE EL: | F12: =VLOOKUP(DATE(YEAR(D13),MONTH(D13),DAY(D13))-1,FACTURACION!O4:P55,2,0) -> 45732 | O12: 99.9 | P12: =O12*0.5 -> 49.95 | Q12: =P12+J11 -> 49.95
B13: DETALLE : | C13: INICIO | D13: =IFERROR(IF(F7="si",VLOOKUP(F9,S19:AH22,5,0),VLOOKUP(T16,S19:AH22,5,0)),"") -> 45717 | E13: CIERRE | F13: =IFERROR(IF(F7="si",VLOOKUP(F9,S19:AH22,8,0),VLOOKUP(T16,S19:AH22,8,0)),"") -> 45747 | O13: 129.9 | P13: =O13*0.5 -> 64.95 | Q13: =P13+J11 -> 64.95
G14: SPEECH CICLO DE FACTURACIÓN
B16: Estimado, para comentarle que en esta oportunidad Entel le estará activando su linea el día | J16: =C7 -> 29 | T16: =IFERROR(VLOOKUP(C7,FACTURACION!F3:G33,2,0),"") -> 1 | U16: =DATE(YEAR(TODAY()),VLOOKUP(C5,FACTURACION!$B$2:$D$14,3,0),C7) -> 45717
B17: La fecha regular de inicio de saldo es | F17: =D13 -> 45717 | G17: Para que usted se mantenga conectado tendrá | L17: =E11 -> 0 DÍA(S) DE PRORRATEO | T17: CICLOS | W17: Inicio de Ciclo | X17: Inicio de Ciclo A | Y17: Inicio de Ciclo B | Z17: Cierre de Ciclo | AA17: FECHA DE ACTIVACIÓN | AB17: Cierre de Ciclo A | AC17: Cierre de Ciclo B | AD17: Cierre de Ciclo C | AG17: Proporcional de la Renta Básica del Nuevo Plan | AH17: TOTAL A PAGAR (Proporcional + Renta Básica) - "APROXIMADAMENTE"
B18: Con un costo de | D18: =J11 -> 0 | E18: aproximadamente solo por este 1er mes. Ademas comentarle que su fecha de pago es el | M18: =F12 -> 45732 | T18: TIPO | U18: DEL | V18: AL | AE18: Dp | AF18: D
B19: Este pago le asegura saldo hasta la fecha | F19: =F13 -> 45747 | S19: 1 | T19: Ciclo 1 | U19: 1 | V19: 30 | W19: =IFERROR(IF($C$7>=U19,Y19,X19),"") -> 45717 | X19: =DATE(YEAR(TODAY()),VLOOKUP($C$5,FACTURACION!$B$2:$D$14,3,0),U19) -> 45689 | Y19: =DATE(YEAR(TODAY()),VLOOKUP($C$5,FACTURACION!$B$2:$D$14,3,0)+1,U19) -> 45717 | Z19: =AC19 -> 45747 | AA19: =DATE(YEAR(TODAY()),VLOOKUP(C5,FACTURACION!$B$2:$D$14,3,0),C7) -> 45717 | AB19: =AC19 -> 45747 | AC19: =EOMONTH(DATE(YEAR(TODAY()),VLOOKUP($C$5,FACTURACION!$B$2:$D$14,3,0)+1,1),0) -> 45747 | AE19: =(Z19-$AA$19)+1 -> 31 | AF19: =(Z19-W19)+1 -> 31 | AG19: =VLOOKUP($D$3,'PLANES REGULARES'!$C$4:$D$12,3,0)/AF19*AE19 -> #REF! | AH19: =VLOOKUP($D$3,'PLANES REGULARES'!$C$4:$D$12,3,0)+AG19 -> #REF!
S20: 3 | T20: Ciclo 3 | U20: 16 | V20: 15 | W20: =IFERROR(IF($C$7>=U20,Y20,X20),"") -> 45732 | X20: =DATE(YEAR(TODAY()),VLOOKUP($C$5,FACTURACION!$B$2:$D$14,3,0),U20) -> 45704 | Y20: =DATE(YEAR(TODAY()),VLOOKUP($C$5,FACTURACION!$B$2:$D$14,3,0)+1,U20) -> 45732 | Z20: =IFERROR(AA20,"") -> 45762 | AA20: =IFERROR(IF($C$7>=U20,AC20,AB20),"") -> 45762 | AB20: =DATE(YEAR(TODAY()),VLOOKUP($C$5,FACTURACION!$B$2:$D$14,3,0)+1,DAY(W20)-1) -> 45731 | AC20: =DATE(YEAR(TODAY()),VLOOKUP($C$5,FACTURACION!$B$2:$D$14,3,0)+2,DAY(W20)-1) -> 45762 | AE20: =(Z20-$AA$19)+1 -> 46 | AF20: =(Z20-W20)+1 -> 31 | AG20: =VLOOKUP($D$3,'PLANES REGULARES'!$C$4:$D$12,3,0)/AF20*AE20 -> #REF! | AH20: =VLOOKUP($D$3,'PLANES REGULARES'!$C$4:$D$12,3,0)+AG20 -> #REF!
S21: 5 | T21: Ciclo 5 | U21: 23 | V21: 22 | W21: =IFERROR(IF($C$7>=U21,Y21,X21),"") -> 45739 | X21: =DATE(YEAR(TODAY()),VLOOKUP($C$5,FACTURACION!$B$2:$D$14,3,0),U21) -> 45711 | Y21: =DATE(YEAR(TODAY()),VLOOKUP($C$5,FACTURACION!$B$2:$D$14,3,0)+1,U21) -> 45739 | Z21: =IFERROR(AA21,"") -> 45769 | AA21: =IFERROR(IF($C$7>=U21,AC21,AB21),"") -> 45769 | AB21: =DATE(YEAR(TODAY()),VLOOKUP($C$5,FACTURACION!$B$2:$D$14,3,0)+1,DAY(W21)-1) -> 45738 | AC21: =DATE(YEAR(TODAY()),VLOOKUP($C$5,FACTURACION!$B$2:$D$14,3,0)+2,DAY(W21)-1) -> 45769 | AE21: =(Z21-$AA$19)+1 -> 53 | AF21: =(Z21-W21)+1 -> 31 | AG21: =VLOOKUP($D$3,'PLANES REGULARES'!$C$4:$D$12,3,0)/AF21*AE21 -> #REF! | AH21: =VLOOKUP($D$3,'PLANES REGULARES'!$C$4:$D$12,3,0)+AG21 -> #REF!
S22: 4 | T22: Ciclo 4 | U22: 9 | V22: 8 | W22: =IFERROR(IF($C$7>=U21,Y22,X22),"") -> 45725 | X22: =DATE(YEAR(TODAY()),VLOOKUP($C$5,FACTURACION!$B$2:$D$14,3,0),U22) -> 45697 | Y22: =DATE(YEAR(TODAY()),VLOOKUP($C$5,FACTURACION!$B$2:$D$14,3,0)+1,U22) -> 45725 | Z22: =IFERROR(AA22,"") -> 45755 | AA22: =IFERROR(IF($C$7>=U22,AC22,AB22),"") -> 45755 | AB22: =DATE(YEAR(TODAY()),VLOOKUP($C$5,FACTURACION!$B$2:$D$14,3,0)+1,DAY(W22)-1) -> 45724 | AC22: =DATE(YEAR(TODAY()),VLOOKUP($C$5,FACTURACION!$B$2:$D$14,3,0)+2,DAY(W22)-1) -> 45755 | AE22: =(Z22-$AA$19)+1 -> 39 | AF22: =(Z22-W22)+1 -> 31
S23: SI
S24: NO
S25: SI
AW35: PLANES SIN DESCUENTO
AX37: COSTO MENSUAL | AY37: DSCTO + PROPORCIONAL
AW39: PLANES | AX39: 39.9 | AY39: =AX39+J11 -> 39.9
AX40: 49.9 | AY40: =AX40+J11 -> 49.9
AW42: IMPORTANTE!!!... NINGUNO DE ESTOS DSCTOS CONVIVE CON PLAN FAMILIA

Sheet OFRECIMIENTO LL.AA
C1: BENEFICIO LINEAS ADICIONALES
C2: CALCULADORA | D2: https://entelpowerperu.github.io/CalculadoraEntelPowerFamiliar/
A6: CLIENTE NUEVO | B6: CLIENTE ENTEL | C6: Plan Tarifario | D6: Cargo Fijo | E6: NACIONAL PERÚ | F6: LARGA DISTANCIA INTERNACIONAL | G6: SMS | H6: Internet | I6: Navegación en Alta Velocidad | J6: APPS ILIMITADAS | K6: 30GB POR 3 MESES | L6: Apps ilimitadas
A8: NO APLICAN DESCUENTOS | C8: Power 49.90 C | D8: 49.9 | E8: Ilimitado | G8: 500 SMS | H8: - | I8: 35 GB | L8: - | M8: - | N8: - | O8: -
A9: MOVISTAR Y BITEL 50% x 6MESES (BASE) 30% X 3 MESES (LL.AA) | B9: 30% X 3 MESES (LL.AA) S/27.93 APLICA MOVISTAR CLARO BITEL | C9: Power 59.90 C | D9: 59.9 | E9: Ilimitado | G9: 500 SMS | H9: - | I9: 65 GB | K9: - | M9: 2.5 GB | N9: Zona América, Europa y Asia | O9: -
A10: CLARO 50% X 12 MESES (BASE) 30% X 3 MESES (LL.AA)
A11: 50% X 12 MESES (LINEA MADRE) 30% X 3 MESES (LINEAS HIJAS S/27.93) SOLO PORTA. (MOV - CLARO Y BITEL) | C11: Power Ilim 69.90 C | D11: 69.9 | E11: Ilimitado | G11: 500 SMS | H11: ilimitado (degradacion) | I11: 100 GB | K11: - | M11: 3.5 GB | N11: Zona América, Europa y Asia | O11: NO
C12: Power Ilim 79.90 C | D12: 79.9 | E12: Ilimitado | G12: ilimitado | H12: ilimitado | I12: ILIMITADO alta velocidad | J12: - | K12: - | M12: 5 GB | N12: Zona América, Europa y Asia | O12: NO
C13: Power Ilim 99.90 C | D13: 99.9 | E13: Ilimitado | G13: ilimitado | H13: ilimitado | I13: ILIMITADO alta velocidad | J13: - | K13: - | M13: 8 GB | N13: Zona América, Europa y Asia | O13: NO
C14: Power Ilim 129.90 C | D14: 129.9 | E14: Ilimitado | G14: ilimitado | H14: ilimitado | I14: ILIMITADO alta velocidad | J14: - | K14: - | M14: 12 GB | N14: Zona América, Europa y Asia | O14: NO
A15: IMPORTANTE!!!... EL PLAN NO CONVIVE CON NINGÚN DESCUENTO ADICIONAL EN OTRAS LINEAS.
L20: ROAMING

Sheet PLANES REGULARES
D1: Planes Tarifarios para Venta Regular y Portabilidad
E2: MINUTOS | H2: DATOS | L2: ROAMING
C3: Plan Tarifario | D3: Cargo Fijo | E3: NACIONAL PERÚ | F3: LARGA DISTANCIA INTERNACIONAL | G3: SMS | H3: Internet | I3: Navegación en Alta Velocidad | J3: APPS ILIMITADAS | K3: 30GB POR 3 MESES | L3: Apps ilimitadas | M3: GB Libres | N3: Zonas | O3: ZONA CAN
A4: NO TIENE DESCUENTO | C4: Power 39.90 | D4: 39.9 | E4: Ilimitado | G4: 500 SMS | H4: - | I4: 25 GB | K4: En PORTA: DUPLICA GB x 3 meses 50GB x 3 meses | L4: - | M4: - | N4: - | O4: MISMOS BENEFICIOS QUE TU PLAN
C5: Power 49.90 | D5: 49.9 | E5: Ilimitado | G5: 500 SMS | H5: - | I5: 40 GB | K5: En PORTA: TIK TOK 30GB x 3 meses | L5: - | M5: - | N5: -
A6: 50% X 12 MESES CLARO MOVISTAR BITEL | C6: Power 59.90 | D6: 59.9 | E6: Ilimitado | G6: 500 SMS | H6: - | I6: 75 GB | K6: - | M6: 3 GB | N6: Zona América, Europa y Asia
C8: Power ILIM 69.90 | D8: 69.9 | E8: Ilimitado | G8: 500 SMS | H8: ilimitado (se degraga) | I8: 100 GB | K8: - | L8: - | M8: 3.5 GB | N8: Zona América, Europa y Asia
C9: Power ILIM 79.90 SD | D9: 79.9 | E9: Ilimitado | G9: SMS Ilimitado | H9: ilimitado | I9: ILIMITADO SD alta velocidad | J9: - | K9: - | M9: 5 GB | N9: Zona América, Europa y Asia
C10: Power ILIM 99.90 SD | D10: 99.9 | E10: Ilimitado | G10: SMS Ilimitado | H10: ilimitado | J10: - | K10: - | M10: 8 GB | N10: Zona América, Europa y Asia
C11: Power ILIM 129.90 SD | D11: 129.9 | E11: Ilimitado | G11: SMS Ilimitado | H11: ilimitado | J11: - | K11: - | L11: WSP, WZ, MAPS, UBER, BOOKING, TripAdvisor,Outlook, Google Traductor, Gmail, Yahoo. | M11: 12 GB | N11: Zona América, Europa y Asia
A12: SE PUEDE COMPARTIR EL TOTAL DE LOS GIGAS DEL PLAN
K14: ROAMING

Sheet FACTURACION
B2: MESES | C2: DIAS | D2: N° | F2: DIA | G2: CICLO | I2: CICLO | J2: TIPO | K2: DEL | L2: AL | N2: Segundo Semestre 2023
B3: ENERO | C3: 31 | D3: 1 | F3: 1 | G3: 4 | I3: 1 | J3: Ciclo 1 | K3: 1 | L3: 30 | N3: Ciclo | O3: Emisión | P3: F.Vcto
B4: FEBRERO | C4: 28 | D4: 2 | F4: 2 | G4: 4 | I4: 3 | J4: Ciclo 3 | K4: 16 | L4: 15 | N4: 3 | O4: 45672 | P4: 45690
B5: MARZO | C5: 31 | D5: 3 | F5: 3 | G5: 4 | I5: 4 | J5: Ciclo 4 | K5: 9 | L5: 8 | N5: 5 | O5: 45679 | P5: 45695
B6: ABRIL | C6: 30 | D6: 4 | F6: 4 | G6: 4 | I6: 5 | J6: Ciclo 5 | K6: 23 | L6: 22 | N6: 1 | O6: 45688 | P6: 45704
B7: MAYO | C7: 31 | D7: 5 | F7: 5 | G7: 4 | N7: 4 | O7: 45665 | P7: 45681
B8: JUNIO | C8: 30 | D8: 6 | F8: 6 | G8: 4 | N8: 3 | O8: 45703 | P8: 45718
B9: JULIO | C9: 31 | D9: 7 | F9: 7 | G9: 4 | I9: CICLO | J9: TIPO | K9: DEL | L9: VTO | N9: 5 | O9: 45710 | P9: 45723
B10: AGOSTO | C10: 31 | D10: 8 | F10: 8 | G10: 4 | I10: 3 | J10: Ciclo 3 | K10: 15 | L10: 2 | N10: 1 | O10: 45716 | P10: 45732
B11: SEPTIEMBRE | C11: 30 | D11: 9 | F11: 9 | G11: 3 | I11: 5 | J11: Ciclo 5 | K11: 22 | L11: 7 | N11: 4 | O11: 45696 | P11: 45712
B12: OCTUBRE | C12: 31 | D12: 10 | F12: 10 | G12: 3 | I12: 1 | J12: Ciclo 1 | K12: 30 | L12: 16 | N12: 3 | O12: 45731 | P12: 45749
B13: NOVIEMBRE | C13: 30 | D13: 11 | F13: 11 | G13: 3 | I13: 4 | J13: Ciclo 4 | K13: 8 | L13: 24 | N13: 5 | O13: 45738 | P13: 45754
B14: DICIEMBRE | C14: 31 | D14: 12 | F14: 12 | G14: 3 | N14: 1 | O14: 45747 | P14: 45763
F15: 13 | G15: 3 | N15: 4 | O15: 45724 | P15: 45740
F16: 14 | G16: 3 | N16: 3 | O16: 45762 | P16: 45779
F17: 15 | G17: 3 | N17: 5 | O17: 45769 | P17: 45784
F18: 16 | G18: 5 | N18: 1 | O18: 45777 | P18: 45793
F19: 17 | G19: 5 | N19: 4 | O19: 45755 | P19: 45771
F20: 18 | G20: 5 | N20: 3 | O20: 45792 | P20: 45810
F21: 19 | G21: 5 | N21: 5 | O21: 45799 | P21: 45815
F22: 20 | G22: 5 | N22: 1 | O22: 45808 | P22: 45824
F23: 21 | G23: 5 | N23: 4 | O23: 45785 | P23: 45801
F24: 22 | G24: 5 | N24: 3 | O24: 45823 | P24: 45840
F25: 23 | G25: 1 | N25: 5 | O25: 45830 | P25: 45845
F26: 24 | G26: 1 | N26: 1 | O26: 45838 | P26: 45854
... F31: 29 | G31: 1 | N31: 4 | O31: 45846 | P31: 45862
F32: 30 | G32: 1 | N32: 3 | O32: 45884 | P32: 2-set-24
F33: 31 | G33: 1 | N33: 5 | O33: 45891 | P33: 7-set-24
N34: 1 | O34: 45900 | P34: 16-set-24
N35: 4 | O35: 45877 | P35: 45893
N36: 3 | O36: 15-set-24 | P36: 45932
N37: 5 | O37: 22-set-24 | P37: 45937
N38: 1 | O38: 30-set-24 | P38: 45946
N39: 4 | O39: 8-set-24 | P39: 24-set-24
N40: 3 | O40: 45945 | P40: 45963
N41: 5 | O41: 45952 | P41: 45968
N42: 1 | O42: 45961 | P42: 45977
N43: 4 | O43: 45938 | P43: 45954
N44: 3 | O44: 45976 | P44: 45993
N45: 5 | O45: 45983 | P45: 45998
...

Sheet REBATE
C3: REBATE
C4: =Hoja1!A4 -> 0
C5: Total general

Sheet EECC LLAA
B2: Evaluación Crediticia Aislada – OneClick

Sheet Hoja1
B1: MI OPERADOR ME BRINDA INTERNET ILIMITADO
A3: OBJECIÓN | B3: MI OPERADOR ME BRINDA INTERNET ILIMITADO
A5: REBATE
A6: Hoy en dia el internet se ha vuelto indispensable en nuestro dia a dia por ello Entel es la unica operadora que entrega todos sus GBS en alta velocidad de forma ilimitada con nuestro plan 89.9 y adicional a ello pagará solo S/44.95 por todo un año..
A7: Total general

Sheet BBDD REBATE
B2: OBJECIÓN | C2: REBATE
B3: SUFRIÓ INCREMENTO EN SU LÍNEA | C3: “Lo entiendo, este cambio se realizó para seguir brindándole un servicio de calidad. Con nuestros planes familia sus líneas adicionales disfrutarán de los mismos beneficios que la línea titular como apps ilimitadas, GB de alta velocidad y más pagando solo s/34.90 por cada línea adicional. !Y no solo eso! le ofrecemos el 20% por 6 meses para sus líneas adicionales .
B4: SE FUE DE ENTEL (Incumplimiento de ofrecimiento) | C4: Lamentamos los inconvenientes, hemos mejorado y estamos listos para escucharlo y brindarle el mejor servicio. Además, con nuestros planes familia sus líneas adicionales disfrutarán de los mismos beneficios que la línea titular por todo el tiempo que quiera pagando solo S/34.90 por cada una. !Y no solo eso! le ofrecemos el 20% por 6 meses para sus líneas adicionales .
B5: INDICA QUE TIENE MEJOR PLAN EN LA COMPETENCIA | C5: Con nuestros planes familia sus líneas adicionales disfrutarán de los mismos beneficios de la línea titular por todo el tiempo que quiera como GB en alta velocidad, apps ilimitadas que no consumen tus GB (indicar app ilimitadas de acuerdo al plan) y más pagando solo s/34.90 por cada una. A diferencia de otros operadores que tiene un plazo de caducidad de promoción. !Y no solo eso! le ofrecemos el 20% por 6 meses para sus líneas adicionales.
B6: ESTOY BIEN CON MI OPERADOR | C6: Me alegro mucho que este conforme con su operador pero cuénteme, ¿Desde cuando su operador no se comunica con usted para ofrecerle alguna promoción? Es por ello que nosotros lo llamamos para ofrecerle promociones donde estaría accediendo por cambiar sus 2 líneas a entel con el plan familiar pagará S/.34.90 por cada línea adicional y obtendrá 20% adicional por 6 meses.
B7: TENGO CONTRATO CON MI OPERADOR | C7: Señor recuerde que actualmente solo debemos permanecer en un operador 31 dias despues tenemos la libertad de seguir eligiendo los beneficios que mas nos convenga y en Entel es donde encontrara las mejores promociones, permitame brevemente mencionarle estos beneficios!!.
B8: NO TENGO COBERTURA EN MI ZONA | C8: Hoy en día tenemos cobertura en muchos centros poblados y lugares alejados, me puede brindar su dirección para validar que cobertura tenemos en su zona por favor. Asi tambien usted puede validar esta información en nuestra página https://www.entel.pe/busqueda-cobertura/. En entel la señal te acompaña.
B9: YA SOY ENTEL | C9: Que buena noticia señor … por ello lo estamos llamando al ser ya cliente de Entel esta accediendo a un abanico de beneficios como el Entel power familiar, donde podrá adquirir una línea adicional a solo 34.9 !Y no solo eso! le ofrecemos el 20% por 6 meses para [todas sus líneas / líneas adicionales] .
B10: NO ESTOY INTERESADO | C10: Permitame explicarle porque hoy en dia Entel se ha convertido en la mejor opción para su linea y no lo digo yo sino nuestros clientes.Contamos con la mejor atención por eso Entel viene siendo reconocida por 9 años consecutivos como la mejor empresa en atención al cliente
B11: LLÁMAME MAS TARDE | C11: Este es el mejor momento para aprovechar los beneficios y promociones de Entel, con un descuento del 50% hasta por un año y adicionalmente accesorios con un costo promocional.
B12: NO TUVE BUENA EXPERIENCIA EN ENTEL | C12: Lamento mucho escuchar ello, por favor reciba las disculpas sobre lo sucedido. Quiero hablarle de lo mucho que hemos mejorado y como va obtener una mejor calidad en el servicio.
B13: SOY PREPAGO NO QUIERO PAGAR MAS | C13: Lo comprendo de igual forma quiero que sepa que al tener una linea pospago comenzaria un score crediticio para que pueda acceder a equipos mas adelante previa evaluacion. Y tambien contamos con un 50% de descuento por todo en año, usted pagaria S/.37.45, pagaria por día un aproximado de 1 sol con 20 céntimos, no deje pasar esta promoción
... B19: QUIERO UN EQUIPO | C19: Entiendo Sr. XX en esta oportunidad le estamos brindando un 50% en su línea a portar, siendo cliente Entel tendrá la facilidad de poder obtener un equipo con nosotros previa evaluación.

Sheet MOTIVO CANCELACIÓN ORDEN
D2: PORQUE MOTIVO SE CANCELO TU ORDEN?
B5: REVISAR EN SIEBEL
B7: 1) Ingresar a solicitud de servicios. 2) Colocar el número de orden en la opción Integration ID. 3) Seleccionas la opción en verde ''IR''. 4) Dar click al número de solicitud. 5) En la opción TIPO buscar la transacción PORTABILIDAD RECHAZADA. 6) En la opción DESCRIPCIÓN econtrarás el motivo.
B14: EJEMPLO
